#VRML_SIM R2021a utf8
WorldInfo {
  coordinateSystem "NUE"
  contactProperties [
    ContactProperties {
      material1 "m1"
      material2 "m2"
      coulombFriction [
        0
      ]
      bounce 0
      bounceVelocity 0
    }
  ]
}
Viewpoint {
  orientation -0.5995414558112754 -0.76016890507598 -0.250386258647079 1.0285592354538473
  position -0.3827769517733749 0.21281081065464505 0.4253045618741377
}
TexturedBackground {
}
TexturedBackgroundLight {
}
RectangleArena {
  translation -0.00776461 0 -0.0389779
  rotation 0 1 0 0.261799
  contactMaterial "m2"
  floorSize 2 1
  floorTileSize 2 1
  floorAppearance PBRAppearance {
    baseColorMap ImageTexture {
      url [
        "Arena_LineFollower.png"
      ]
    }
    metalness 0
  }
}
Robot {
  translation -0.14192800675859468 0.0006061442684835508 0.2589589747767459
  rotation 1.3031044416347678e-05 0.9999999997708946 -1.6982416374027285e-05 -1.3089953074008833
  children [
    DistanceSensor {
      translation -0.03 0.02 0.042
      rotation 0 0 1 -1.57
      children [
        Shape {
          appearance PBRAppearance {
            roughness 1
            metalness 0
          }
          geometry Box {
            size 0.005 0.005 0.005
          }
        }
      ]
      name "ir2"
      type "infra-red"
      numberOfRays 10
      aperture 0.1
    }
    DistanceSensor {
      translation 0.03 0.02 0.042
      rotation 0 0 -1 1.57
      children [
        Shape {
          appearance PBRAppearance {
            roughness 1
            metalness 0
          }
          geometry Box {
            size 0.005 0.005 0.005
          }
        }
      ]
      name "ir1"
      type "infra-red"
      numberOfRays 10
      aperture 0.1
    }
    DistanceSensor {
      translation 0 0.02 0.05
      rotation 0 0 1 -1.57
      children [
        Shape {
          appearance PBRAppearance {
            roughness 1
            metalness 0
          }
          geometry Box {
            size 0.005 0.005 0.005
          }
        }
      ]
      name "ir0"
      type "infra-red"
      numberOfRays 10
      aperture 0.1
    }
    DEF body Transform {
      translation 0 0.05 0
      children [
        Shape {
          appearance PBRAppearance {
            baseColor 0.7 0.5 1
            roughness 1
            metalness 0
          }
          geometry Cylinder {
            height 0.1
            radius 0.05
          }
        }
      ]
    }
    HingeJoint {
      jointParameters HingeJointParameters {
        position -4.8630524088517507e-17
        anchor 0.05 0.039 0
      }
      device [
        RotationalMotor {
          name "motor2"
        }
      ]
      endPoint Solid {
        translation 0.05 0.039 0
        rotation -2.4334632652640407e-17 2.4315262044258753e-17 1 1.57
        children [
          DEF wheel Shape {
            appearance PBRAppearance {
              roughness 1
              metalness 0
            }
            geometry Cylinder {
              height 0.02
              radius 0.04
            }
          }
        ]
        name "solid(1)"
        boundingObject USE wheel
        physics Physics {
        }
        linearVelocity -2.1522969609300908e-09 4.704723891129376e-06 -8.032446961581389e-09
        angularVelocity -2.006798303042519e-07 4.246351161300612e-16 5.37722321082666e-08
      }
    }
    HingeJoint {
      jointParameters HingeJointParameters {
        position 1.236460169108222e-16
        anchor -0.05 0.039 0
      }
      device [
        RotationalMotor {
          name "motor1"
        }
      ]
      endPoint Solid {
        translation -0.050008 0.039 0
        rotation 2.1894405794440543e-16 -6.18230084554111e-17 1 1.57
        children [
          DEF wheel Shape {
            appearance PBRAppearance {
              roughness 1
              metalness 0
            }
            geometry Cylinder {
              height 0.02
              radius 0.04
            }
          }
        ]
        boundingObject USE wheel
        physics Physics {
        }
        linearVelocity -2.1495807110102307e-09 4.68435552635984e-06 -8.022309611105151e-09
        angularVelocity -2.006798149715978e-07 4.2521563767326524e-16 5.377222780344056e-08
      }
    }
  ]
  contactMaterial "m1"
  boundingObject USE body
  physics Physics {
  }
  controller "robotics_round_2"
  linearVelocity -2.7419715703783685e-09 4.6460946860635544e-06 -1.0233133662891871e-08
  angularVelocity -2.006700046386129e-07 7.71740767788464e-16 5.376959970070806e-08
}
