#VRML_SIM R2021a utf8
WorldInfo {
  coordinateSystem "NUE"
  contactProperties [
    ContactProperties {
      material1 "m1"
      material2 "m2"
      coulombFriction [
        0
      ]
      bounce 0
      bounceVelocity 0
    }
  ]
}
Viewpoint {
  orientation -0.9837403445859236 0.16396640603019264 0.0732799572018841 0.7601733033524174
  position 0.2129320759630693 1.6721324293698974 1.8281955971277066
}
TexturedBackground {
}
TexturedBackgroundLight {
}
RectangleArena {
  translation -0.00776461 0 -0.0389779
  rotation 0 1 0 0.261799
  contactMaterial "m2"
  floorSize 2 1
  floorTileSize 2 1
  floorAppearance PBRAppearance {
    baseColorMap ImageTexture {
      url [
        "Arena_LineFollower.png"
      ]
    }
    metalness 0
  }
}
Robot {
  translation -0.161246 0 0.267
  rotation 1.3031044416347678e-05 0.9999999997708946 -1.6982416374027285e-05 -1.3089953074008833
  children [
    DistanceSensor {
      translation -0.0210021 0.02 0.022
      rotation 0.25054991757034345 0.2507489175048735 0.9350666923677843 -1.6370953071795862
      children [
        Shape {
          appearance PBRAppearance {
            roughness 1
            metalness 0
          }
          geometry Box {
            size 0.002 0.002 0.002
          }
        }
      ]
      name "ir2"
      type "infra-red"
      numberOfRays 10
      aperture 0.1
    }
    DistanceSensor {
      translation 0.021 0.02 0.022
      rotation 0.25054991757034345 0.2507489175048735 0.9350666923677843 -1.6370853071795866
      children [
        Shape {
          appearance PBRAppearance {
            roughness 1
            metalness 0
          }
          geometry Box {
            size 0.002 0.002 0.002
          }
        }
      ]
      name "ir1"
      type "infra-red"
      numberOfRays 10
      aperture 0.1
    }
    DistanceSensor {
      translation 0 0.02 0.03
      rotation 0.4471420556928879 0.4474990557373533 0.7744730964629535 -1.822865307179586
      children [
        Shape {
          appearance PBRAppearance {
            roughness 1
            metalness 0
          }
          geometry Box {
            size 0.002 0.002 0.002
          }
        }
      ]
      name "ir0"
      type "infra-red"
      numberOfRays 10
      aperture 0.1
    }
    DEF body Transform {
      translation 0 0.035 0
      children [
        Shape {
          appearance PBRAppearance {
            baseColor 0.7 0.5 1
            roughness 1
            metalness 0
          }
          geometry Cylinder {
            height 0.07
            radius 0.03
          }
        }
      ]
    }
    HingeJoint {
      jointParameters HingeJointParameters {
        position -4.8630524088517507e-17
        anchor 0.033 0.0195 0
      }
      device [
        RotationalMotor {
          name "motor2"
        }
      ]
      endPoint Solid {
        translation 0.033 0.0195 0
        rotation -9.733853061056182e-16 9.726104817703523e-16 1 1.57
        children [
          DEF wheel Shape {
            appearance PBRAppearance {
              roughness 1
              metalness 0
            }
            geometry Cylinder {
              height 0.005
              radius 0.02
            }
          }
        ]
        name "solid(1)"
        boundingObject USE wheel
        physics Physics {
        }
      }
    }
    HingeJoint {
      jointParameters HingeJointParameters {
        position 1.236460169108222e-16
        anchor -0.033 0.0195 0
      }
      device [
        RotationalMotor {
          name "motor1"
        }
      ]
      endPoint Solid {
        translation -0.033 0.0195 -1.1746371606528112e-18
        rotation 2.6319621740025358e-15 -2.4729203382164473e-15 1 1.57
        children [
          DEF wheel Shape {
            appearance PBRAppearance {
              roughness 1
              metalness 0
            }
            geometry Cylinder {
              height 0.005
              radius 0.02
            }
          }
        ]
        boundingObject USE wheel
        physics Physics {
        }
      }
    }
  ]
  contactMaterial "m1"
  boundingObject USE body
  physics Physics {
  }
  controller "robotics_round_2"
}
